<mujoco> 
	<worldbody>
		<light diffuse=".5 .5 .5" pos="0 0 3" dir="0 0 -1"/>
		<geom type="plane" size="10 10 0.1" rgba="1 .88 0.72 0.8"/>
		<body pos="0 0 0.5">
			<joint type="free"/>
			<geom type="box" size=".5 .4 .1" rgba="0 1 1 1"/>

			<body pos="0.5 0.75 -0.3">
				<joint name="left_back" type="hinge" axis="0 1 0"/>
				<geom type="sphere" size=".05" rgba="0 1 1 1"/>
			</body>	

			<body pos="0.5 -0.75 -0.3">
				<joint name="right_back" type="hinge" axis="0 1 0"/>
				<geom type="sphere" size=".05" rgba="0 1 1 1"/>
			</body>	

			<body pos="-0.5 0.75 -0.3">
				<joint name="left_front" type="hinge" axis="0 1 0"/>
				<geom type="sphere" size=".05" rgba="0 1 1 1"/>
			</body>	

			<body pos="-0.5 -0.75 -0.3">
				<joint name="right_front" type="hinge" axis="0 1 0"/>
				<geom type="sphere" size=".05" rgba="0 1 1 1"/>
			</body>	

		</body>
	</worldbody>

	<actuator>
		<motor joint="left_back" name="lb_motor"/>
		<motor joint="right_back" name="rb_motor"/>
		<motor joint="left_front" name="lf_motor"/>
		<motor joint="right_front" name="rf_motor"/>
	</actuator>

</mujoco>
